Workbook

Sheet Read Me
B2: Tollesbury Arts - Online Gallery
B3: Budget, tech stack and cost-recovery model
B4: Prepared 17 August 2026 - all figures ex-VAT
B6: HOW TO USE THIS WORKBOOK
B7: Assumptions | C7: Every input lives here. Change these and the whole workbook updates. Nothing else needs editing.
B8: Setup Budget | C8: One-off build cost: labour at market vs community rate, plus non-labour setup items.
B9: Running Costs | C9: Annual running cost under three hosting scenarios, side by side.
B10: Income | C10: Joining fees plus commission, and the break-even artist count.
B11: Summary | C11: Year 1 (grant-funded) and Year 2 onward (self-funding). The bottom line.
B12: Tech Stack | C12: The full specification: theme, every plugin, email, and the accounts the CIC must own.
B14: CELL COLOUR LEGEND
B15: Blue text | C15: An input you can change. All of them are on the Assumptions tab.
B16: Black text | C16: A calculated figure. Do not overwrite - it will break the model.
B17: Green text | C17: Pulled from another tab.
B18: Yellow fill | C18: A key assumption or an item you must confirm before relying on it.
B21: THE HEADLINE CONCLUSIONS
B22: 1. | C22: Managed UK WordPress hosting costs about the same per year as running your own Lightsail server - so the self-hosting saving is not worth the sysadmin burden, or the risk of the CIC depending on one volunteer.
B23: 2. | C23: Do NOT put the shop on the same EC2 instance as the wiki. A compromised WooCommerce store must not share a box with anything else, and WooCommerce's cron and PHP tuning can destabilise a wiki.
B24: 3. | C24: Do NOT run mail from Plesk on an AWS box. AWS blocks outbound port 25 by default and a fresh IP has no sending reputation - order confirmations will land in spam. Use Amazon SES for transactional email and Brevo free for the newsletter.
B25: 4. | C25: Artist joining fees alone very nearly cover the annual running cost. That is the point of charging them: income does not depend on sales volume, which in year one is unknowable.
B26: 5. | C26: ONE COMMISSION RATE FOR EVERYONE. This is the big change from the first draft. Two different rates was the only reason we needed the paid Dokan licence at £118/yr - which was eating 65% of the gallery's entire annual margin. A single rate runs on the free version, and the Featured tier sells placement and profile instead of a discount.
B27: 6. | C27: That one change is worth about £230 a year: the surplus roughly doubles, and break-even drops from 27 artists to around 22 - which is the difference between a launch condition you might miss and one you will clear.
B28: 7. | C28: It is also easier to explain. 'Everyone pays 12%' survives a village meeting; two tiers with a £400 crossover point does not. Use the sensitivity strip on the Income tab to pick the rate before you commit to it.
B29: 8. | C29: The build is genuinely worth £5,000-6,500 at market rates. Put that figure in the grant application, then show your community discount as a visible line - funders count it as match funding.

Sheet Assumptions
B2: Assumptions
B3: Blue cells are inputs. Yellow means confirm before you rely on it.
A5: Currency
B6: USD to GBP exchange rate | C6: 0.79 | D6: CONFIRM - several tools are priced in USD. Update this to today's rate.
A8: Artists and pricing
B9: Number of participating artists | C9: 30 | D9: Your estimate. Do not launch below the break-even count on the Income tab.
B10: Proportion choosing the Featured tier | C10: 0.33 | D10: Artists who want homepage placement and a fuller profile page.
B11: Featured joining fee (per year) | C11: 60 | D11: Buys placement and profile - NOT a commission discount. That is what keeps us on the free Dokan.
B12: Standard joining fee (per year) | C12: 20 | D12: Keeps the barrier to entry low but guarantees a floor of income.
B13: Commission on sales - ONE rate for everyone | C13: 0.12 | D13: The key change. A single rate runs on free Dokan Lite. Compare: a commercial gallery takes 40-50%.
A15: Sales
B16: Estimated annual gross sales | C16: 4000 | D16: Deliberately modest for year one. Flex this to test sensitivity.
B17: Average order value | C17: 150 | D17: Drives the number of transactions, and so the Stripe fixed fees.
B18: Stripe percentage fee | C18: 0.015 | D18: Standard UK cards. Source: stripe.com/gb/pricing
B19: Stripe fixed fee per transaction | C19: 0.2 | D19: Source: stripe.com/gb/pricing
A21: Jonathan's fees
B22: Monthly maintenance retainer | C22: 50 | D22: Your proposal. Market rate for WordPress maintenance is £150-500/month, so this is very generous.
B23: Day rate - full market | C23: 500 | D23: UK freelance WordPress work runs £40-80/hour. £500/day sits mid-range for ecommerce.
B24: Day rate - community rate | C24: 250 | D24: Roughly half. This is what to actually invoice if the grant lands.
B25: Day rate - absolute floor | C25: 150 | D25: Below this you will resent the project by month four. Do not go here.
A27: Other
B28: Contingency on running costs | C28: 0.1 | D28: Price rises, an extra plugin, a domain renewal you forgot. Always carry this.

Sheet Setup Budget
B2: Setup Budget - one-off build
B3: What the build is worth, and what to charge for it
A5: Labour | C5: Days | D5: At market | E5: Community | F5: What this covers
B6: Discovery, scoping and committee workshops | C6: 1 | D6: =$C6*Assumptions!$C$23 -> 500 | E6: =$C6*Assumptions!$C$24 -> 250 | F6: Agreeing what it is, who does what, and writing it down before a line of code.
B7: Artist agreement, T&Cs and compliance pages | C7: 1.5 | D7: =$C7*Assumptions!$C$23 -> 750 | E7: =$C7*Assumptions!$C$24 -> 375 | F7: The load-bearing document. Agency wording, trust-money clause, 23 items of pre-contract info.
B8: Server build: WordPress, security, backups, SSL, email deliverability | C8: 1.5 | D8: =$C8*Assumptions!$C$23 -> 750 | E8: =$C8*Assumptions!$C$24 -> 375 | F8: Including SES/DKIM/SPF setup so order emails actually arrive.
B9: Theme build and design to match tollesbury.arts | C9: 2.5 | D9: =$C9*Assumptions!$C$23 -> 1250 | E9: =$C9*Assumptions!$C$24 -> 625 | F9: Gallery and artist page templates, product layout, mobile. The bit people judge you on.
B10: WooCommerce and Dokan config: commission tiers, shipping bands, payouts | C10: 1.5 | D10: =$C10*Assumptions!$C$23 -> 750 | E10: =$C10*Assumptions!$C$24 -> 375 | F10: Two commission tiers, gallery-wide flat postage bands, quarterly payout reporting.
B11: Stripe, checkout, order workflow and end-to-end testing | C11: 1 | D11: =$C11*Assumptions!$C$23 -> 500 | E11: =$C11*Assumptions!$C$24 -> 250 | F11: Including test purchases, refund path, and the cancellation flow.
B12: Artist onboarding: 30 listings, photo guidance, data-entry process | C12: 2 | D12: =$C12*Assumptions!$C$23 -> 1000 | E12: =$C12*Assumptions!$C$24 -> 500 | F12: The artists do not log in - a volunteer lists on their behalf. This is that setup.
B13: PWA integration, launch, volunteer training and documentation | C13: 1.5 | D13: =$C13*Assumptions!$C$23 -> 750 | E13: =$C13*Assumptions!$C$24 -> 375 | F13: Linking tollesbury.app across, and training whoever runs orders day to day.
B14: Total labour | C14: =SUM(C6:C13) -> 12.5 | D14: =SUM(D6:D13) -> 6250 | E14: =SUM(E6:E13) -> 3125
A16: Non-labour setup | D16: Cost | F16: Note
B17: CIC incorporation fee | D17: 65 | F17: CONFIRM with Companies House - the CIC fee differs from a standard Ltd.
B18: Independent legal review of the artist agreement | D18: 300 | F18: Optional but worth it. This document carries the VAT, FCA and consumer-law positions.
B19: Product photography kit (light tent, backdrop, tripod) | D19: 80 | F19: Consistent white-background shots are what make a small gallery look professional.
B20: Theme licence (Blocksy Pro) - optional | D20: 55 | F20: Start on the free version. Only buy if you actually hit a limit.
B21: Total non-labour | D21: =SUM(D17:D20) -> 500
A23: The invoice - how to present it
B24: Full market value of the build | D24: =$D$14+$D$21 -> 6750 | F24: Use THIS number in the grant application. It is the honest value of the work.
B25: Less: community contribution (your discount) | D25: =-($D$14-$E$14) -> -3125 | F25: Show it as a visible line. Funders count it as match funding, and it stops the committee anchoring on the low number forever.
B26: PAYABLE - community rate | D26: =$E$14+$D$21 -> 3625
B28: For reference: at your absolute floor day rate | D28: =$C$14*Assumptions!$C$25+$D$21 -> 2375 | F28: Do not go here. You would be donating around 12 days of skilled work.
A30: Payment terms to insist on
B31: - 40% on signature, 30% at design sign-off, 30% at launch. Never build on a promise.
B32: - Make the contract CONDITIONAL ON GRANT AWARD. If the money does not land, nobody owes anybody anything.
B33: - Itemise the community contribution on every invoice so its value stays visible.
B34: - If you are a CIC director, the board must approve your contract with you abstaining, minute it, and disclose it in the annual CIC34 report. Cleanest: do not be a director, just a contractor.

Sheet Running Costs
B2: Annual Running Costs
B3: Three hosting scenarios, everything else held equal
A5: Cost item | C5: A: Managed UK | D5: B: Lightsail 2GB | E5: C: Lightsail 4GB | F5: Note
B6: Hosting / server | C6: =180 -> 180 | D6: =12*12*Assumptions!$C$6 -> 113.76 | E6: =24*12*Assumptions!$C$6 -> 227.52 | F6: A: managed WordPress host at ~£15/mo, backups and updates included. B/C: Lightsail bundle, fixed price.
B7: Server snapshots / offsite backup | C7: =0 -> 0 | D7: =3*12*Assumptions!$C$6 -> 28.44 | E7: =3*12*Assumptions!$C$6 -> 28.44 | F7: Included in managed hosting. On Lightsail you pay for automatic snapshots.
B8: Control panel (Plesk) | C8: =0 -> 0 | D8: =0 -> 0 | E8: =0 -> 0 | F8: You need NONE. Plesk is £8-15/mo and buys you nothing here. Use the Bitnami image or plain Ubuntu.
B9: Domain: tollesbury.arts | C9: =25 -> 25 | D9: =25 -> 25 | E9: =25 -> 25 | F9: CONFIRM your actual renewal price - novelty TLDs renew far above the intro rate.
B10: Domain: tollesbury.app | C10: =15 -> 15 | D10: =15 -> 15 | E10: =15 -> 15
B11: Dokan Lite (multi-vendor) | C11: =0 -> 0 | D11: =0 -> 0 | E11: =0 -> 0 | F11: FREE. Starter at $149/yr buys per-vendor commission rates - which a single rate makes unnecessary. VERIFY with Dokan pre-sales that Lite does one global rate before relying on this.
B12: Image optimisation (ShortPixel) | C12: =35 -> 35 | D12: =35 -> 35 | E12: =35 -> 35 | F12: An art site is nothing but large images. Worth paying for.
B13: Transactional email (Amazon SES) | C13: =1 -> 1 | D13: =1 -> 1 | E13: =1 -> 1 | F13: $0.10 per 1,000 emails. No branding. This is your order confirmations - it must not go to spam.
B14: Newsletter (Brevo free tier) | C14: =0 -> 0 | D14: =0 -> 0 | E14: =0 -> 0 | F14: 300 emails/day free, ~9,000/month. Plenty. Note: free tier adds Brevo branding, so keep it off order emails.
B15: Social scheduling (Buffer free tier) | C15: =0 -> 0 | D15: =0 -> 0 | E15: =0 -> 0 | F15: Free: 3 channels, 10 queued posts each. Enough to start. Paid is ~$6/channel/mo if outgrown.
B16: Mailboxes (Zoho Mail Lite x3 users) | C16: =36 -> 36 | D16: =36 -> 36 | E16: =36 -> 36 | F16: ~£1/user/mo. Zoho's free tier does 5 users on a custom domain but is webmail-only.
B17: ICO data protection fee | C17: =47 -> 47 | D17: =47 -> 47 | E17: =47 -> 47 | F17: Tier 1, £52 less the £5 direct-debit discount. You are storing customer addresses, so this applies.
B18: SMS order alerts to artists | C18: =25 -> 25 | D18: =25 -> 25 | E18: =25 -> 25 | F18: Essential. These artists do not read email - if you rely on email, sales will not get posted.
B19: Uptime monitoring, password vault, SSL | C19: =0 -> 0 | D19: =0 -> 0 | E19: =0 -> 0 | F19: UptimeRobot free, Bitwarden free, Let's Encrypt free.
B20: Subtotal - infrastructure and tools | C20: =SUM(C6:C19) -> 364 | D20: =SUM(D6:D19) -> 326.2 | E20: =SUM(E6:E19) -> 439.96
B21: Contingency | C21: =C20*Assumptions!$C$28 -> 36.4 | D21: =D20*Assumptions!$C$28 -> 32.62 | E21: =E20*Assumptions!$C$28 -> 43.996 | F21: Price rises and the plugin you did not know you needed.
B22: Stripe processing fees | C22: =Income!$C$7 -> 65.333333 | D22: =Income!$C$7 -> 65.333333 | E22: =Income!$C$7 -> 65.333333 | F22: From the Income tab. Recommendation: the artist agreement should deduct these from the artist's proceeds alongside commission.
B23: Jonathan - maintenance retainer | C23: =Assumptions!$C$22*12 -> 600 | D23: =Assumptions!$C$22*12 -> 600 | E23: =Assumptions!$C$22*12 -> 600 | F23: Your £50/month. Covers updates, backups checks, security, small changes.
B24: TOTAL ANNUAL RUNNING COST | C24: =C20+C21+C22+C23 -> 1065.7333 | D24: =D20+D21+D22+D23 -> 1024.1533 | E24: =E20+E21+E22+E23 -> 1149.2893
B26: Monthly equivalent | C26: =C24/12 -> 88.811111 | D26: =D24/12 -> 85.346111 | E26: =E24/12 -> 95.774111
A28: Which scenario, and why
B29: - RECOMMENDED: Scenario A, managed UK WordPress hosting. It costs within a few pounds a year of running your own Lightsail box, but the host handles updates, backups, security patching and support - so the CIC is not one volunteer's holiday away from a dead shop.
B30: - If you do self-host, use LIGHTSAIL, not EC2. Lightsail bundles instance, storage and 3TB of data transfer into one fixed monthly price. That is precisely the fix for your $26-to-$65 problem: EC2's headline price excludes the EBS volume, snapshots, the now-chargeable public IPv4 address, data egress, Route 53 zones and CloudWatch.
B31: - Open the server in the CIC'S OWN AWS or hosting account, not yours. They pay the provider directly, you hold admin access. You should never be fronting their infrastructure bills on a personal card.
B32: - Scenario C (4GB) only if Dokan plus 30 vendors and heavy image traffic actually needs it. Start at 2GB or managed, and measure before upgrading.

Sheet Income
B2: Income and Break-even
B3: Driven entirely by the Assumptions tab
A5: Transaction volume
B6: Number of orders | C6: =Assumptions!$C$16/Assumptions!$C$17 -> 26.666667 | D6: Gross sales divided by average order value.
B7: Stripe fees on all sales | C7: =Assumptions!$C$16*Assumptions!$C$18+C6*Assumptions!$C$19 -> 65.333333 | D7: 1.5% plus 20p per order. Feeds through to the Running Costs tab.
A9: Joining fees - the income floor
B10: Featured-tier artists | C10: =Assumptions!$C$9*Assumptions!$C$10 -> 9.9
B11: Standard-tier artists | C11: =Assumptions!$C$9-C10 -> 20.1
B12: Featured joining fee income | C12: =C10*Assumptions!$C$11 -> 594
B13: Standard joining fee income | C13: =C11*Assumptions!$C$12 -> 402
B14: Total joining fees | C14: =C12+C13 -> 996 | D14: This arrives whether or not anything sells. It is why you charge it.
A16: Commission - one rate for everyone
B17: Commission on all sales | C17: =Assumptions!$C$16*Assumptions!$C$13 -> 480 | D17: A single rate is what keeps this on the FREE Dokan Lite and saves £118 a year.
B19: TOTAL INCOME | C19: =C14+C17 -> 1476
A21: The number a sceptical artist will work out for themselves
B22: Effective total take, as a % of sales | C22: =IFERROR($C$19/Assumptions!$C$16,0) -> 0.369 | D22: Joining fees PLUS commission, over gross sales. At low sales volume this is much higher than the headline commission rate - be ready for the question.
B23: Sales needed for effective take to fall below 20% | C23: =IFERROR($C$19/0.2,0) -> 7380 | D23: The joining fee is fixed, so the more the gallery sells, the better the deal looks. Say this out loud at the artists' meeting.
A25: Break-even
B26: Annual running cost (Scenario A) | C26: ='Running Costs'!$C$24 -> 1065.7333
B27: Surplus / (deficit) | C27: =Income!$C$19-C26 -> 410.26667
B28: Average income per artist | C28: =IFERROR(Income!$C$19/Assumptions!$C$9,0) -> 49.2
B29: Artists needed to break even | C29: =IFERROR(ROUNDUP('Running Costs'!$C$24/(C28),0),0) -> 22 | D29: Make this your launch condition. Below it, the project does not pay for itself.
A31: Reading this honestly
B32: - Income is far more sensitive to ARTIST COUNT than to sales volume, because joining fees do most of the work. Recruiting artists is the job, not marketing to buyers.
B33: - If sales are zero, joining fees still cover most of the running cost. If artists are few, nothing saves you. Plan accordingly.
B34: - Year one should be grant-funded so the fee structure only has to work from year two, once you know real numbers.

Sheet Summary
B2: Summary
B3: Year 1 grant-funded, Year 2 onward self-funding
B5: Item | C5: Year 1 | D5: Year 2+ | E5: Note
B6: Build cost payable to Jonathan (community rate) | C6: ='Setup Budget'!$D$26 -> 3625 | D6: 0 | E6: One-off. Grant-funded, and conditional on the grant landing.
B7: Annual running cost (Scenario A) | C7: ='Running Costs'!$C$24 -> 1065.7333 | D7: ='Running Costs'!$C$24 -> 1065.7333 | E7: Includes your £50/month retainer and contingency.
B8: TOTAL COST | C8: =SUM(C6:C7) -> 4690.7333 | D8: =SUM(D6:D7) -> 1065.7333
B10: Grant funding sought (Taylor Fund and others) | C10: =C8 -> 4690.7333 | D10: 0 | E10: Ask for the FULL year-one cost including the first year's running. Do not ask for just the build.
B11: Artist joining fees and commission | C11: 0 | D11: =Income!$C$19 -> 1476 | E11: Waive fees in year one as a launch incentive - it gets you to 30 artists far faster.
B12: TOTAL INCOME | C12: =SUM(C10:C11) -> 4690.7333 | D12: =SUM(D10:D11) -> 1476
B14: SURPLUS / (DEFICIT) | C14: =C12-C8 -> 0 | D14: =D12-D8 -> 410.26667
A16: What Jonathan receives
B17: Build fee (one-off, community rate) | C17: ='Setup Budget'!$D$26 -> 3625 | D17: 0
B18: Maintenance retainer | C18: =Assumptions!$C$22*12 -> 600 | D18: =Assumptions!$C$22*12 -> 600 | E18: Note: under £1,000/yr may fall inside HMRC's trading allowance if you have no other self-employment income. Check with an accountant.
B19: Total to Jonathan | C19: =SUM(C17:C18) -> 4225 | D19: =SUM(D17:D18) -> 600
B20: Value donated to the community | C20: ='Setup Budget'!$D$24-'Setup Budget'!$D$26 -> 3125 | E20: Put this on the invoice and in the grant application. It is real, and it counts.
A22: Why one commission rate - the change that pays for itself | C22: Two rates | D22: One rate | E22: Note
B23: Superseded blended commission rate | C23: 0.095 | D23: =Assumptions!$C$13 -> 0.12 | E23: The old model's 5% / 15% split worked out at 9.5% blended.
B24: Commission income | C24: =Assumptions!$C$16*$C$23 -> 380 | D24: =Assumptions!$C$16*Assumptions!$C$13 -> 480
B25: Joining fees | C25: =Income!$C$14 -> 996 | D25: =Income!$C$14 -> 996 | E25: Unchanged - the Featured tier still costs £60, it just buys placement instead of a discount.
B26: Total income | C26: =SUM(C24:C25) -> 1376 | D26: =SUM(D24:D25) -> 1476
B27: Dokan licence | C27: =149*Assumptions!$C$6*(1+Assumptions!$C$28) -> 129.481 | D27: 0 | E27: Starter at $149/yr, plus its share of contingency. Lite is free.
B28: All other running costs | C28: ='Running Costs'!$C$24 -> 1065.7333 | D28: ='Running Costs'!$C$24 -> 1065.7333
B29: Total cost | C29: =SUM(C27:C28) -> 1195.2143 | D29: =SUM(D27:D28) -> 1065.7333
B30: SURPLUS | C30: =C26-C29 -> 180.78567 | D30: =D26-D29 -> 410.26667
B31: Gain from switching | D31: =D30-C30 -> 229.481 | E31: Per year, every year. Plus one fewer licence to renew and one fewer thing to explain to artists.
A33: Picking the rate - sensitivity | C33: Total income | D33: Surplus | E33: Effective take on artists
B34: 0.08 | C34: =Income!$C$14+Assumptions!$C$16*$B34 -> 1316 | D34: =C34-D29 -> 250.26667 | E34: =IFERROR(C34/Assumptions!$C$16,0) -> 0.329
B35: 0.1 | C35: =Income!$C$14+Assumptions!$C$16*$B35 -> 1396 | D35: =C35-D29 -> 330.26667 | E35: =IFERROR(C35/Assumptions!$C$16,0) -> 0.349
B36: 0.12 | C36: =Income!$C$14+Assumptions!$C$16*$B36 -> 1476 | D36: =C36-D29 -> 410.26667 | E36: =IFERROR(C36/Assumptions!$C$16,0) -> 0.369
B37: 0.15 | C37: =Income!$C$14+Assumptions!$C$16*$B37 -> 1596 | D37: =C37-D29 -> 530.26667 | E37: =IFERROR(C37/Assumptions!$C$16,0) -> 0.399
B38: Effective take counts joining fees AND commission over gross sales - the sum a sceptical artist will do. It looks high at £4,000 of turnover because the fixed joining fee is spread over few sales; it falls fast as sales grow. 12% is highlighted as the recommended balance: it roughly doubles the surplus versus the old model while staying far below the 40-50% a commercial gallery takes.
A40: Decisions still open
B41: - DOMAINS: you want control, funders want the CIC to own its assets. Resolution - keep ownership, grant the CIC a written royalty-free licence, with a clause transferring the domains to them free of charge on request or if you step down. That satisfies both. Do not sell them - it creates a taxable transaction for the sake of £50.
B42: - ACCOUNTS: Stripe, AWS/hosting, Brevo, Buffer, Google Analytics must ALL be in the CIC's name, with credentials in a shared vault and two committee members holding recovery access. This is the single thing that prevents the classic 'the chap who ran our website moved away' disaster.
B43: - ORDER ADMIN: a named volunteer must handle orders and ring artists. Not you. Make it a condition of the build.
B44: - LAUNCH GATE: do not go live below the break-even artist count on the Income tab.

Sheet Tech Stack
B2: Tech Stack Specification
B3: Everything that gets installed, and what it costs
A5: Foundation | C5: Choice | D5: £/year | E5: Why
B6: CMS | C6: WordPress | D6: 0 | E6: You already know it. Full design control, no platform cut, the CIC owns its data.
B7: Shop | C7: WooCommerce | D7: 0 | E7: Unique artworks work fine as stock-of-1 products.
B8: Theme | C8: Blocksy (free) | D8: 0 | E8: Image-forward, fast, block-editor native, genuinely good WooCommerce integration. Kadence is an equally good alternative.
B9: Theme - do NOT use | C9: ThemeForest 'art gallery' themes | D9: avoid | E9: Bloated, poorly maintained, and they lock the CIC into a dead codebase. This matters more than the £40 you save.
B10: Multi-vendor | C10: Dokan Lite (free) | D10: 0 | E10: Each artist gets an isolated store, own products, own orders, no visibility of anyone else's. Free version is enough because we run ONE commission rate.
B11: Multi-vendor - if you change tack | C11: Dokan Starter, $149/yr | D11: 118 | E11: Only needed for PER-VENDOR commission rates. Verify with Dokan pre-sales that Lite does a single global rate before you rely on the free tier.
A13: Payments | C13: Choice | D13: £/year | E13: Why
B14: Gateway | C14: Stripe for WooCommerce (official) | D14: 0 | E14: 1.5% + 20p on UK cards. Hosted fields, so PCI stays at SAQ A.
B15: Do NOT build | C15: Custom card form | D15: avoid | E15: It drags you into full PCI DSS scope for no benefit whatsoever.
B16: Payouts | C16: Manual bank transfer, quarterly | D16: 0 | E16: Matches how the local physical gallery already works, and the artists understand it. No Stripe Connect onboarding to lose people to.
A18: Email - two separate jobs, do not confuse them | C18: Choice | D18: £/year | E18: Why
B19: Transactional (orders) | C19: Amazon SES + FluentSMTP | D19: 1 | E19: £0.08 per 1,000. No branding. This is order confirmations - if they hit spam you have no business.
B20: Newsletter | C20: Brevo free tier | D20: 0 | E20: 300/day, ~9,000/month. Keep it OFF order emails: the free tier stamps Brevo branding on everything.
B21: Mailboxes | C21: Zoho Mail Lite x3 | D21: 36 | E21: info@, sales@, treasurer@. ~£1/user/mo. Free tier does 5 users but webmail-only.
B22: Do NOT use | C22: Plesk mail on AWS | D22: avoid | E22: AWS blocks outbound port 25 by default and needs a support request plus reverse DNS. A fresh IP has no sending reputation. Not worth it.
A24: Operations | C24: Choice | D24: £/year | E24: Why
B25: Security | C25: Wordfence Free | D25: 0 | E25: Firewall and malware scanning. Adequate at this scale.
B26: Backups | C26: Host backups + UpdraftPlus | D26: 0 | E26: Test a restore once. An untested backup is not a backup.
B27: Caching | C27: Host cache or LiteSpeed Cache | D27: 0 | E27: Free. Only buy WP Rocket if the host gives you nothing.
B28: Images | C28: ShortPixel | D28: 35 | E28: An art site is nothing but big images. This is the one paid plugin that always earns back.
B29: SEO | C29: Rank Math Free | D29: 0 | E29: Local search matters more than you think for a village trail.
B30: Forms | C30: Fluent Forms Free | D30: 0 | E30: The artist submission form - a volunteer types listings from these.
B31: Cookie consent | C31: CookieYes or Complianz Free | D31: 0 | E31: Required, and free.
B32: Invoices | C32: WooCommerce PDF Invoices | D32: 0 | E32: Packing slips and invoices. The volunteer will thank you.
B33: SMS alerts | C33: Twilio or Brevo SMS credits | D33: 25 | E33: CRITICAL. Your artists do not read email. Without this, orders silently never get posted.
B34: Monitoring | C34: UptimeRobot Free | D34: 0 | E34: Tells you the shop is down before a buyer does.
B35: Passwords | C35: Bitwarden Free | D35: 0 | E35: Shared vault. Two committee members hold recovery access. Non-negotiable.
A37: Accounts the CIC must own in its own name | C37: Choice | D37: £/year | E37: Why
B38: Stripe | C38: CIC's own account | D38: 0 | E38: Merchant of record must be the CIC. Never your personal account - it becomes your taxable income.
B39: Hosting / AWS | C39: CIC's own account | D39: 0 | E39: They pay the provider directly. You hold admin access, not the credit card.
B40: Brevo | C40: CIC's own account | D40: 0 | E40: Yes, separate from yours. Same reason as everything else here.
B41: Buffer | C41: CIC's own account | D41: 0 | E41: Free tier: 3 channels, 10 queued posts each. Enough to start.
B42: Analytics | C42: CIC's own GA4 or Plausible | D42: 0 | E42: Grant reports will ask for visitor numbers. Set it up on day one.
B43: Domains | C43: Licensed from you, transferable | D43: 0 | E43: See the Summary tab - keep ownership, licence to them, with a transfer-on-request clause.
A45: Explicitly rejected | C45: Choice | D45: £/year | E45: Why
B46: Same EC2 box as the wiki | C46: Rejected | D46: - | E46: A compromised shop must not share a server with anything else, and WooCommerce cron/PHP tuning can destabilise the wiki.
B47: Raw EC2 for the shop | C47: Rejected | D47: - | E47: This is your $26-to-$65 problem: the headline price excludes EBS, snapshots, the chargeable IPv4 address, egress, Route 53 and CloudWatch.
...
